2024-01-30 12:16:30,027 INFO    Thread-14 (_run_job):74817 [wandb_setup.py:_flush():76] Current SDK version is 0.16.1
2024-01-30 12:16:30,027 INFO    Thread-14 (_run_job):74817 [wandb_setup.py:_flush():76] Configure stats pid to 74817
2024-01-30 12:16:30,027 INFO    Thread-14 (_run_job):74817 [wandb_setup.py:_flush():76] Loading settings from /Users/songzeyang/.config/wandb/settings
2024-01-30 12:16:30,027 INFO    Thread-14 (_run_job):74817 [wandb_setup.py:_flush():76] Loading settings from /Users/songzeyang/Documents/GitHub/Data_Distill_with_NC/wandb/settings
2024-01-30 12:16:30,027 INFO    Thread-14 (_run_job):74817 [wandb_setup.py:_flush():76] Loading settings from environment variables: {'project': 'hyper_sweep_4_', 'entity': 'data-distillation-with-nc', 'root_dir': '/Users/songzeyang/Documents/GitHub/Data_Distill_with_NC', 'run_id': '7eu2xpjy', 'sweep_param_path': '/Users/songzeyang/Documents/GitHub/Data_Distill_with_NC/wandb/sweep-cr28hdxq/config-7eu2xpjy.yaml', 'sweep_id': 'cr28hdxq'}
2024-01-30 12:16:30,027 INFO    Thread-14 (_run_job):74817 [wandb_setup.py:_flush():76] Applying setup settings: {'_disable_service': False}
2024-01-30 12:16:30,027 INFO    Thread-14 (_run_job):74817 [wandb_setup.py:_flush():76] Inferring run settings from compute environment: {'program': '<python with no main file>'}
2024-01-30 12:16:30,027 INFO    Thread-14 (_run_job):74817 [wandb_init.py:_log_setup():524] Logging user logs to /Users/songzeyang/Documents/GitHub/Data_Distill_with_NC/wandb/run-20240130_121630-7eu2xpjy/logs/debug.log
2024-01-30 12:16:30,028 INFO    Thread-14 (_run_job):74817 [wandb_init.py:_log_setup():525] Logging internal logs to /Users/songzeyang/Documents/GitHub/Data_Distill_with_NC/wandb/run-20240130_121630-7eu2xpjy/logs/debug-internal.log
2024-01-30 12:16:30,028 INFO    Thread-14 (_run_job):74817 [wandb_init.py:_jupyter_setup():470] configuring jupyter hooks <wandb.sdk.wandb_init._WandbInit object at 0x16c27d750>
2024-01-30 12:16:30,029 INFO    Thread-14 (_run_job):74817 [wandb_init.py:init():564] calling init triggers
2024-01-30 12:16:30,029 INFO    Thread-14 (_run_job):74817 [wandb_init.py:init():571] wandb.init called with sweep_config: {'batch_size': 64, 'depth': 4, 'learning_rate': 0.1, 'model': 'MLP', 'optimizer': 'Adam', 'width': 4096}
config: {}
2024-01-30 12:16:30,029 INFO    Thread-14 (_run_job):74817 [wandb_init.py:init():614] starting backend
2024-01-30 12:16:30,029 INFO    Thread-14 (_run_job):74817 [wandb_init.py:init():618] setting up manager
2024-01-30 12:16:30,036 INFO    Thread-14 (_run_job):74817 [backend.py:_multiprocessing_setup():105] multiprocessing start_methods=spawn,fork,forkserver, using: spawn
2024-01-30 12:16:30,036 INFO    Thread-14 (_run_job):74817 [wandb_init.py:init():624] backend started and connected
2024-01-30 12:16:30,052 INFO    Thread-14 (_run_job):74817 [wandb_run.py:_config_callback():1342] config_cb None None {'batch_size': 64, 'depth': 4, 'learning_rate': 0.1, 'model': 'MLP', 'optimizer': 'Adam', 'width': 4096}
2024-01-30 12:16:30,058 INFO    Thread-14 (_run_job):74817 [wandb_run.py:_label_probe_notebook():1294] probe notebook
2024-01-30 12:16:30,058 INFO    Thread-14 (_run_job):74817 [wandb_run.py:_label_probe_notebook():1304] Unable to probe notebook: 'NoneType' object has no attribute 'get'
2024-01-30 12:16:30,058 INFO    Thread-14 (_run_job):74817 [wandb_init.py:init():716] updated telemetry
2024-01-30 12:16:30,083 INFO    Thread-14 (_run_job):74817 [wandb_init.py:init():749] communicating run to backend with 90.0 second timeout
2024-01-30 12:16:30,594 INFO    Thread-14 (_run_job):74817 [wandb_run.py:_on_init():2254] communicating current version
2024-01-30 12:16:30,733 INFO    Thread-14 (_run_job):74817 [wandb_run.py:_on_init():2263] got version response upgrade_message: "wandb version 0.16.2 is available!  To upgrade, please run:\n $ pip install wandb --upgrade"

2024-01-30 12:16:30,734 INFO    Thread-14 (_run_job):74817 [wandb_init.py:init():800] starting run threads in backend
2024-01-30 12:16:34,442 INFO    Thread-14 (_run_job):74817 [wandb_run.py:_console_start():2233] atexit reg
2024-01-30 12:16:34,442 INFO    Thread-14 (_run_job):74817 [wandb_run.py:_redirect():2088] redirect: wrap_raw
2024-01-30 12:16:34,442 INFO    Thread-14 (_run_job):74817 [wandb_run.py:_redirect():2153] Wrapping output streams.
2024-01-30 12:16:34,442 INFO    Thread-14 (_run_job):74817 [wandb_run.py:_redirect():2178] Redirects installed.
2024-01-30 12:16:34,442 INFO    Thread-14 (_run_job):74817 [wandb_init.py:init():841] run started, returning control to user process
2024-01-30 12:16:34,443 INFO    Thread-14 (_run_job):74817 [wandb_run.py:_finish():1962] finishing run data-distillation-with-nc/hyper_sweep_4_/7eu2xpjy
2024-01-30 12:16:34,443 INFO    Thread-14 (_run_job):74817 [jupyter.py:save_history():445] not saving jupyter history
2024-01-30 12:16:34,443 INFO    Thread-14 (_run_job):74817 [jupyter.py:save_ipynb():373] not saving jupyter notebook
2024-01-30 12:16:34,443 INFO    Thread-14 (_run_job):74817 [wandb_init.py:_jupyter_teardown():452] cleaning up jupyter logic
2024-01-30 12:16:34,443 INFO    Thread-14 (_run_job):74817 [wandb_run.py:_atexit_cleanup():2202] got exitcode: 1
2024-01-30 12:16:34,444 INFO    Thread-14 (_run_job):74817 [wandb_run.py:_restore():2185] restore
2024-01-30 12:16:34,444 INFO    Thread-14 (_run_job):74817 [wandb_run.py:_restore():2191] restore done
2024-01-30 12:16:38,468 ERROR   Thread-14 (_run_job):74817 [ipython.py:update():120] Socket operation on non-socket
Traceback (most recent call last):
  File "/Users/songzeyang/anaconda3/lib/python3.11/site-packages/wandb/sdk/wandb_config.py", line 162, in __getattr__
    return self.__getitem__(key)
           ^^^^^^^^^^^^^^^^^^^^^
  File "/Users/songzeyang/anaconda3/lib/python3.11/site-packages/wandb/sdk/wandb_config.py", line 130, in __getitem__
    return self._items[key]
           ~~~~~~~~~~~^^^^^
KeyError: 'dataset'

The above exception was the direct cause of the following exception:

Traceback (most recent call last):
  File "/var/folders/50/9xzt17gx7hz47b3vjql39fjh0000gn/T/ipykernel_74817/2262831725.py", line 6, in train_n_validate
    trainloader, testloader, num_classes = make_dataset(config.dataset,
                                                        ^^^^^^^^^^^^^^
  File "/Users/songzeyang/anaconda3/lib/python3.11/site-packages/wandb/sdk/wandb_config.py", line 164, in __getattr__
    raise AttributeError(
AttributeError: <class 'wandb.sdk.wandb_config.Config'> object has no attribute 'dataset'

During handling of the above exception, another exception occurred:

Traceback (most recent call last):
  File "/Users/songzeyang/anaconda3/lib/python3.11/site-packages/wandb/sdk/lib/ipython.py", line 113, in update
    self._progress.value = value
    ^^^^^^^^^^^^^^^^^^^^
  File "/Users/songzeyang/anaconda3/lib/python3.11/site-packages/traitlets/traitlets.py", line 729, in __set__
    self.set(obj, value)
  File "/Users/songzeyang/anaconda3/lib/python3.11/site-packages/traitlets/traitlets.py", line 718, in set
    obj._notify_trait(self.name, old_value, new_value)
  File "/Users/songzeyang/anaconda3/lib/python3.11/site-packages/traitlets/traitlets.py", line 1501, in _notify_trait
    self.notify_change(
  File "/Users/songzeyang/anaconda3/lib/python3.11/site-packages/ipywidgets/widgets/widget.py", line 693, in notify_change
    self.send_state(key=name)
  File "/Users/songzeyang/anaconda3/lib/python3.11/site-packages/ipywidgets/widgets/widget.py", line 579, in send_state
    self._send(msg, buffers=buffers)
  File "/Users/songzeyang/anaconda3/lib/python3.11/site-packages/ipywidgets/widgets/widget.py", line 818, in _send
    self.comm.send(data=msg, buffers=buffers)
  File "/Users/songzeyang/anaconda3/lib/python3.11/site-packages/comm/base_comm.py", line 113, in send
    self.publish_msg(
  File "/Users/songzeyang/anaconda3/lib/python3.11/site-packages/ipykernel/comm/comm.py", line 36, in publish_msg
    self.kernel.session.send(
  File "/Users/songzeyang/anaconda3/lib/python3.11/site-packages/jupyter_client/session.py", line 859, in send
    stream.send_multipart(to_send, copy=copy)
  File "/Users/songzeyang/anaconda3/lib/python3.11/site-packages/ipykernel/iostream.py", line 330, in send_multipart
    return self.io_thread.send_multipart(*args, **kwargs)
           ^^^^^^^^^^^^^^^^^^^^^^^^^^^^^^^^^^^^^^^^^^^^^^
  File "/Users/songzeyang/anaconda3/lib/python3.11/site-packages/ipykernel/iostream.py", line 260, in send_multipart
    self.schedule(lambda: self._really_send(*args, **kwargs))
  File "/Users/songzeyang/anaconda3/lib/python3.11/site-packages/ipykernel/iostream.py", line 251, in schedule
    self._event_pipe.send(b"")
  File "/Users/songzeyang/anaconda3/lib/python3.11/site-packages/zmq/sugar/socket.py", line 618, in send
    return super().send(data, flags=flags, copy=copy, track=track)
           ^^^^^^^^^^^^^^^^^^^^^^^^^^^^^^^^^^^^^^^^^^^^^^^^^^^^^^^
  File "zmq/backend/cython/socket.pyx", line 740, in zmq.backend.cython.socket.Socket.send
  File "zmq/backend/cython/socket.pyx", line 781, in zmq.backend.cython.socket.Socket.send
  File "zmq/backend/cython/socket.pyx", line 137, in zmq.backend.cython.socket._check_closed
zmq.error.ZMQError: Socket operation on non-socket
2024-01-30 12:16:38,481 INFO    Thread-14 (_run_job):74817 [wandb_run.py:_restore():2185] restore
2024-01-30 12:16:38,481 INFO    Thread-14 (_run_job):74817 [wandb_run.py:_restore():2191] restore done
2024-01-30 12:16:39,483 ERROR   Thread-14 (_run_job):74817 [wandb_run.py:_atexit_cleanup():2223] Problem finishing run
Traceback (most recent call last):
  File "/Users/songzeyang/anaconda3/lib/python3.11/site-packages/wandb/sdk/wandb_config.py", line 162, in __getattr__
    return self.__getitem__(key)
           ^^^^^^^^^^^^^^^^^^^^^
  File "/Users/songzeyang/anaconda3/lib/python3.11/site-packages/wandb/sdk/wandb_config.py", line 130, in __getitem__
    return self._items[key]
           ~~~~~~~~~~~^^^^^
KeyError: 'dataset'

The above exception was the direct cause of the following exception:

Traceback (most recent call last):
  File "/var/folders/50/9xzt17gx7hz47b3vjql39fjh0000gn/T/ipykernel_74817/2262831725.py", line 6, in train_n_validate
    trainloader, testloader, num_classes = make_dataset(config.dataset,
                                                        ^^^^^^^^^^^^^^
  File "/Users/songzeyang/anaconda3/lib/python3.11/site-packages/wandb/sdk/wandb_config.py", line 164, in __getattr__
    raise AttributeError(
AttributeError: <class 'wandb.sdk.wandb_config.Config'> object has no attribute 'dataset'

During handling of the above exception, another exception occurred:

Traceback (most recent call last):
  File "/Users/songzeyang/anaconda3/lib/python3.11/site-packages/wandb/sdk/lib/ipython.py", line 113, in update
    self._progress.value = value
    ^^^^^^^^^^^^^^^^^^^^
  File "/Users/songzeyang/anaconda3/lib/python3.11/site-packages/traitlets/traitlets.py", line 729, in __set__
    self.set(obj, value)
  File "/Users/songzeyang/anaconda3/lib/python3.11/site-packages/traitlets/traitlets.py", line 718, in set
    obj._notify_trait(self.name, old_value, new_value)
  File "/Users/songzeyang/anaconda3/lib/python3.11/site-packages/traitlets/traitlets.py", line 1501, in _notify_trait
    self.notify_change(
  File "/Users/songzeyang/anaconda3/lib/python3.11/site-packages/ipywidgets/widgets/widget.py", line 693, in notify_change
    self.send_state(key=name)
  File "/Users/songzeyang/anaconda3/lib/python3.11/site-packages/ipywidgets/widgets/widget.py", line 579, in send_state
    self._send(msg, buffers=buffers)
  File "/Users/songzeyang/anaconda3/lib/python3.11/site-packages/ipywidgets/widgets/widget.py", line 818, in _send
    self.comm.send(data=msg, buffers=buffers)
  File "/Users/songzeyang/anaconda3/lib/python3.11/site-packages/comm/base_comm.py", line 113, in send
    self.publish_msg(
  File "/Users/songzeyang/anaconda3/lib/python3.11/site-packages/ipykernel/comm/comm.py", line 36, in publish_msg
    self.kernel.session.send(
  File "/Users/songzeyang/anaconda3/lib/python3.11/site-packages/jupyter_client/session.py", line 859, in send
    stream.send_multipart(to_send, copy=copy)
  File "/Users/songzeyang/anaconda3/lib/python3.11/site-packages/ipykernel/iostream.py", line 330, in send_multipart
    return self.io_thread.send_multipart(*args, **kwargs)
           ^^^^^^^^^^^^^^^^^^^^^^^^^^^^^^^^^^^^^^^^^^^^^^
  File "/Users/songzeyang/anaconda3/lib/python3.11/site-packages/ipykernel/iostream.py", line 260, in send_multipart
    self.schedule(lambda: self._really_send(*args, **kwargs))
  File "/Users/songzeyang/anaconda3/lib/python3.11/site-packages/ipykernel/iostream.py", line 251, in schedule
    self._event_pipe.send(b"")
  File "/Users/songzeyang/anaconda3/lib/python3.11/site-packages/zmq/sugar/socket.py", line 618, in send
    return super().send(data, flags=flags, copy=copy, track=track)
           ^^^^^^^^^^^^^^^^^^^^^^^^^^^^^^^^^^^^^^^^^^^^^^^^^^^^^^^
  File "zmq/backend/cython/socket.pyx", line 740, in zmq.backend.cython.socket.Socket.send
  File "zmq/backend/cython/socket.pyx", line 781, in zmq.backend.cython.socket.Socket.send
  File "zmq/backend/cython/socket.pyx", line 137, in zmq.backend.cython.socket._check_closed
zmq.error.ZMQError: Socket operation on non-socket

During handling of the above exception, another exception occurred:

Traceback (most recent call last):
  File "/Users/songzeyang/anaconda3/lib/python3.11/site-packages/wandb/sdk/wandb_run.py", line 2211, in _atexit_cleanup
    self._on_finish()
  File "/Users/songzeyang/anaconda3/lib/python3.11/site-packages/wandb/sdk/wandb_run.py", line 2451, in _on_finish
    _ = exit_handle.wait(timeout=-1, on_progress=self._on_progress_exit)
        ^^^^^^^^^^^^^^^^^^^^^^^^^^^^^^^^^^^^^^^^^^^^^^^^^^^^^^^^^^^^^^^^
  File "/Users/songzeyang/anaconda3/lib/python3.11/site-packages/wandb/sdk/lib/mailbox.py", line 303, in wait
    on_progress(progress_handle)
  File "/Users/songzeyang/anaconda3/lib/python3.11/site-packages/wandb/sdk/wandb_run.py", line 2430, in _on_progress_exit
    self._footer_file_pusher_status_info(
  File "/Users/songzeyang/anaconda3/lib/python3.11/site-packages/wandb/sdk/wandb_run.py", line 3648, in _footer_file_pusher_status_info
    Run._footer_single_run_file_pusher_status_info(
  File "/Users/songzeyang/anaconda3/lib/python3.11/site-packages/wandb/sdk/wandb_run.py", line 3699, in _footer_single_run_file_pusher_status_info
    printer.progress_update(line, percent_done)
  File "/Users/songzeyang/anaconda3/lib/python3.11/site-packages/wandb/sdk/lib/printer.py", line 288, in progress_update
    self._progress.update(percent_done, text)
  File "/Users/songzeyang/anaconda3/lib/python3.11/site-packages/wandb/sdk/lib/ipython.py", line 121, in update
    wandb.termwarn(
  File "/Users/songzeyang/anaconda3/lib/python3.11/site-packages/wandb/errors/term.py", line 50, in termwarn
    _log(
  File "/Users/songzeyang/anaconda3/lib/python3.11/site-packages/wandb/errors/term.py", line 95, in _log
    click.echo(line, file=sys.stderr, nl=newline)
  File "/Users/songzeyang/anaconda3/lib/python3.11/site-packages/click/utils.py", line 298, in echo
    file.write(out)  # type: ignore
    ^^^^^^^^^^^^^^^
  File "/Users/songzeyang/anaconda3/lib/python3.11/site-packages/ipykernel/iostream.py", line 648, in write
    self._schedule_flush()
  File "/Users/songzeyang/anaconda3/lib/python3.11/site-packages/ipykernel/iostream.py", line 545, in _schedule_flush
    self.pub_thread.schedule(_schedule_in_thread)
  File "/Users/songzeyang/anaconda3/lib/python3.11/site-packages/ipykernel/iostream.py", line 251, in schedule
    self._event_pipe.send(b"")
  File "/Users/songzeyang/anaconda3/lib/python3.11/site-packages/zmq/sugar/socket.py", line 618, in send
    return super().send(data, flags=flags, copy=copy, track=track)
           ^^^^^^^^^^^^^^^^^^^^^^^^^^^^^^^^^^^^^^^^^^^^^^^^^^^^^^^
  File "zmq/backend/cython/socket.pyx", line 740, in zmq.backend.cython.socket.Socket.send
  File "zmq/backend/cython/socket.pyx", line 781, in zmq.backend.cython.socket.Socket.send
  File "zmq/backend/cython/socket.pyx", line 137, in zmq.backend.cython.socket._check_closed
zmq.error.ZMQError: Socket operation on non-socket
2024-01-30 12:16:39,490 INFO    Thread-14 (_run_job):74817 [wandb_run.py:_finish():1962] finishing run data-distillation-with-nc/hyper_sweep_4_/7eu2xpjy
2024-01-30 12:16:39,490 INFO    Thread-14 (_run_job):74817 [jupyter.py:save_history():445] not saving jupyter history
2024-01-30 12:16:39,490 INFO    Thread-14 (_run_job):74817 [jupyter.py:save_ipynb():373] not saving jupyter notebook
2024-01-30 12:16:39,490 INFO    Thread-14 (_run_job):74817 [wandb_init.py:_jupyter_teardown():452] cleaning up jupyter logic
2024-01-30 12:17:57,229 INFO    MainThread:74817 [wandb_run.py:_finish():1962] finishing run data-distillation-with-nc/hyper_sweep_4_/7eu2xpjy
2024-01-30 12:17:57,231 INFO    MainThread:74817 [jupyter.py:save_history():445] not saving jupyter history
2024-01-30 12:17:57,231 INFO    MainThread:74817 [jupyter.py:save_ipynb():373] not saving jupyter notebook
2024-01-30 12:17:57,231 INFO    MainThread:74817 [wandb_init.py:_jupyter_teardown():452] cleaning up jupyter logic
2024-01-30 12:39:30,277 ERROR   MainThread:74817 [internal_api.py:execute():373] 400 response executing GraphQL.
2024-01-30 12:39:30,278 ERROR   MainThread:74817 [internal_api.py:execute():374] {"errors":[{"message":"Invalid sweep config: Sweep config must contain method section","path":["upsertSweep"]}],"data":{"upsertSweep":null}}
2024-01-30 12:48:10,312 INFO    MainThread:74817 [pyagent.py:run():314] Starting sweep agent: entity=None, project=None, count=5
2024-01-30 12:48:52,192 INFO    MainThread:74817 [pyagent.py:run():314] Starting sweep agent: entity=None, project=None, count=5
2024-01-30 12:52:44,142 INFO    MainThread:74817 [wandb_setup.py:_flush():76] Current SDK version is 0.16.1
2024-01-30 12:52:44,143 INFO    MainThread:74817 [wandb_setup.py:_flush():76] Configure stats pid to 74817
2024-01-30 12:52:44,143 INFO    MainThread:74817 [wandb_setup.py:_flush():76] Loading settings from /Users/songzeyang/.config/wandb/settings
2024-01-30 12:52:44,143 INFO    MainThread:74817 [wandb_setup.py:_flush():76] Loading settings from /Users/songzeyang/Documents/GitHub/Data_Distill_with_NC/wandb/settings
2024-01-30 12:52:44,143 INFO    MainThread:74817 [wandb_setup.py:_flush():76] Loading settings from environment variables: {'project': 'hyper_sweep_4_', 'entity': 'data-distillation-with-nc', 'root_dir': '/Users/songzeyang/Documents/GitHub/Data_Distill_with_NC', 'run_id': '7eu2xpjy', 'sweep_param_path': '/Users/songzeyang/Documents/GitHub/Data_Distill_with_NC/wandb/sweep-cr28hdxq/config-7eu2xpjy.yaml', 'sweep_id': 'cr28hdxq'}
2024-01-30 12:52:44,143 INFO    MainThread:74817 [wandb_setup.py:_flush():76] Applying setup settings: {'_disable_service': False}
2024-01-30 12:52:44,143 INFO    MainThread:74817 [wandb_setup.py:_flush():76] Inferring run settings from compute environment: {'program': '<python with no main file>'}
2024-01-30 12:52:44,143 INFO    MainThread:74817 [wandb_init.py:_log_setup():524] Logging user logs to /Users/songzeyang/Documents/GitHub/Data_Distill_with_NC/wandb/run-20240130_125244-7eu2xpjy/logs/debug.log
2024-01-30 12:52:44,143 INFO    MainThread:74817 [wandb_init.py:_log_setup():525] Logging internal logs to /Users/songzeyang/Documents/GitHub/Data_Distill_with_NC/wandb/run-20240130_125244-7eu2xpjy/logs/debug-internal.log
2024-01-30 12:52:44,143 INFO    MainThread:74817 [wandb_init.py:_jupyter_setup():470] configuring jupyter hooks <wandb.sdk.wandb_init._WandbInit object at 0x10995e850>
2024-01-30 12:52:44,143 INFO    MainThread:74817 [wandb_init.py:init():564] calling init triggers
2024-01-30 12:52:44,143 INFO    MainThread:74817 [wandb_init.py:init():571] wandb.init called with sweep_config: {'batch_size': 64, 'depth': 4, 'learning_rate': 0.1, 'model': 'MLP', 'optimizer': 'Adam', 'width': 4096}
config: {'method': 'grid', 'metric': {'name': 'loss', 'goal': 'minimize'}, 'parameters': {'model': {'values': ['MLP', 'ResNet18_adapt']}, 'learning_rate': {'values': [0.1, 0.05, 0.001]}, 'optimizer': {'values': ['Adam', 'SGD', 'LBFGS']}, 'width': {'values': [1024, 2048, 4096]}, 'depth': {'values': [4, 8, 12]}, 'batch_size': {'values': [64, 256, 2048]}}}
2024-01-30 12:52:44,143 INFO    MainThread:74817 [wandb_init.py:init():589] re-initializing run, found existing run on stack: 7eu2xpjy
2024-01-30 12:52:44,144 INFO    MainThread:74817 [wandb_run.py:_finish():1962] finishing run data-distillation-with-nc/hyper_sweep_4_/7eu2xpjy
2024-01-30 12:52:44,144 INFO    MainThread:74817 [jupyter.py:save_history():445] not saving jupyter history
2024-01-30 12:52:44,144 INFO    MainThread:74817 [jupyter.py:save_ipynb():373] not saving jupyter notebook
2024-01-30 12:52:44,144 INFO    MainThread:74817 [wandb_init.py:_jupyter_teardown():452] cleaning up jupyter logic
