2024-01-30 16:02:17,275 INFO    Thread-11 (_run_job):91700 [wandb_setup.py:_flush():76] Current SDK version is 0.16.1
2024-01-30 16:02:17,276 INFO    Thread-11 (_run_job):91700 [wandb_setup.py:_flush():76] Configure stats pid to 91700
2024-01-30 16:02:17,276 INFO    Thread-11 (_run_job):91700 [wandb_setup.py:_flush():76] Loading settings from /Users/songzeyang/.config/wandb/settings
2024-01-30 16:02:17,276 INFO    Thread-11 (_run_job):91700 [wandb_setup.py:_flush():76] Loading settings from /Users/songzeyang/Documents/GitHub/Data_Distill_with_NC/wandb/settings
2024-01-30 16:02:17,276 INFO    Thread-11 (_run_job):91700 [wandb_setup.py:_flush():76] Loading settings from environment variables: {'project': 'hyper_sweep_4_neural_search', 'entity': 'data-distillation-with-nc', 'root_dir': '/Users/songzeyang/Documents/GitHub/Data_Distill_with_NC', 'run_id': 'yji3kod5', 'sweep_param_path': '/Users/songzeyang/Documents/GitHub/Data_Distill_with_NC/wandb/sweep-cqyijzfv/config-yji3kod5.yaml', 'sweep_id': 'cqyijzfv'}
2024-01-30 16:02:17,276 INFO    Thread-11 (_run_job):91700 [wandb_setup.py:_flush():76] Applying setup settings: {'_disable_service': False}
2024-01-30 16:02:17,276 INFO    Thread-11 (_run_job):91700 [wandb_setup.py:_flush():76] Inferring run settings from compute environment: {'program': '<python with no main file>'}
2024-01-30 16:02:17,277 INFO    Thread-11 (_run_job):91700 [wandb_init.py:_log_setup():524] Logging user logs to /Users/songzeyang/Documents/GitHub/Data_Distill_with_NC/wandb/run-20240130_160217-yji3kod5/logs/debug.log
2024-01-30 16:02:17,277 INFO    Thread-11 (_run_job):91700 [wandb_init.py:_log_setup():525] Logging internal logs to /Users/songzeyang/Documents/GitHub/Data_Distill_with_NC/wandb/run-20240130_160217-yji3kod5/logs/debug-internal.log
2024-01-30 16:02:17,277 INFO    Thread-11 (_run_job):91700 [wandb_init.py:_jupyter_setup():470] configuring jupyter hooks <wandb.sdk.wandb_init._WandbInit object at 0x168c87810>
2024-01-30 16:02:17,278 INFO    Thread-11 (_run_job):91700 [wandb_init.py:init():564] calling init triggers
2024-01-30 16:02:17,279 INFO    Thread-11 (_run_job):91700 [wandb_init.py:init():571] wandb.init called with sweep_config: {'batch_size': 64, 'depth': 4, 'epochs': 10, 'learning_rate': 0.1, 'loss': 'CrossEntropy', 'model': 'MLP', 'optimizer': 'Adam', 'width': 2048}
config: {}
2024-01-30 16:02:17,279 INFO    Thread-11 (_run_job):91700 [wandb_init.py:init():614] starting backend
2024-01-30 16:02:17,279 INFO    Thread-11 (_run_job):91700 [wandb_init.py:init():618] setting up manager
2024-01-30 16:02:17,288 INFO    Thread-11 (_run_job):91700 [backend.py:_multiprocessing_setup():105] multiprocessing start_methods=spawn,fork,forkserver, using: spawn
2024-01-30 16:02:17,288 INFO    Thread-11 (_run_job):91700 [wandb_init.py:init():624] backend started and connected
2024-01-30 16:02:17,304 INFO    Thread-11 (_run_job):91700 [wandb_run.py:_config_callback():1342] config_cb None None {'batch_size': 64, 'depth': 4, 'epochs': 10, 'learning_rate': 0.1, 'loss': 'CrossEntropy', 'model': 'MLP', 'optimizer': 'Adam', 'width': 2048}
2024-01-30 16:02:17,311 INFO    Thread-11 (_run_job):91700 [wandb_run.py:_label_probe_notebook():1294] probe notebook
2024-01-30 16:02:17,311 INFO    Thread-11 (_run_job):91700 [wandb_run.py:_label_probe_notebook():1304] Unable to probe notebook: 'NoneType' object has no attribute 'get'
2024-01-30 16:02:17,311 INFO    Thread-11 (_run_job):91700 [wandb_init.py:init():716] updated telemetry
2024-01-30 16:02:17,336 INFO    Thread-11 (_run_job):91700 [wandb_init.py:init():749] communicating run to backend with 90.0 second timeout
2024-01-30 16:02:18,289 INFO    Thread-11 (_run_job):91700 [wandb_run.py:_on_init():2254] communicating current version
2024-01-30 16:02:18,407 INFO    Thread-11 (_run_job):91700 [wandb_run.py:_on_init():2263] got version response upgrade_message: "wandb version 0.16.2 is available!  To upgrade, please run:\n $ pip install wandb --upgrade"

2024-01-30 16:02:18,407 INFO    Thread-11 (_run_job):91700 [wandb_init.py:init():800] starting run threads in backend
2024-01-30 16:02:22,052 INFO    Thread-11 (_run_job):91700 [wandb_run.py:_console_start():2233] atexit reg
2024-01-30 16:02:22,052 INFO    Thread-11 (_run_job):91700 [wandb_run.py:_redirect():2088] redirect: wrap_raw
2024-01-30 16:02:22,052 INFO    Thread-11 (_run_job):91700 [wandb_run.py:_redirect():2153] Wrapping output streams.
2024-01-30 16:02:22,052 INFO    Thread-11 (_run_job):91700 [wandb_run.py:_redirect():2178] Redirects installed.
2024-01-30 16:02:22,053 INFO    Thread-11 (_run_job):91700 [wandb_init.py:init():841] run started, returning control to user process
2024-01-30 16:02:31,586 INFO    MainThread:91700 [jupyter.py:save_ipynb():373] not saving jupyter notebook
2024-01-30 16:02:31,586 INFO    MainThread:91700 [wandb_init.py:_pause_backend():435] pausing backend
2024-01-30 16:02:50,042 INFO    Thread-11 (_run_job):91700 [wandb_run.py:_finish():1962] finishing run data-distillation-with-nc/hyper_sweep_4_neural_search/yji3kod5
2024-01-30 16:02:50,042 INFO    Thread-11 (_run_job):91700 [jupyter.py:save_history():445] not saving jupyter history
2024-01-30 16:02:50,042 INFO    Thread-11 (_run_job):91700 [jupyter.py:save_ipynb():373] not saving jupyter notebook
2024-01-30 16:02:50,042 INFO    Thread-11 (_run_job):91700 [wandb_init.py:_jupyter_teardown():452] cleaning up jupyter logic
2024-01-30 16:02:50,043 INFO    Thread-11 (_run_job):91700 [wandb_run.py:_atexit_cleanup():2202] got exitcode: 1
2024-01-30 16:02:50,043 INFO    Thread-11 (_run_job):91700 [wandb_run.py:_restore():2185] restore
2024-01-30 16:02:50,043 INFO    Thread-11 (_run_job):91700 [wandb_run.py:_restore():2191] restore done
2024-01-30 16:02:52,053 ERROR   Thread-11 (_run_job):91700 [ipython.py:update():120] Socket operation on non-socket
Traceback (most recent call last):
  File "/var/folders/50/9xzt17gx7hz47b3vjql39fjh0000gn/T/ipykernel_91700/3855940507.py", line 14, in train_n_validate
    print("The number of class in our training set is ", num_classes)
  File "/Users/songzeyang/anaconda3/lib/python3.11/site-packages/wandb/sdk/lib/redirect.py", line 640, in write
    self._old_write(data)
  File "/Users/songzeyang/anaconda3/lib/python3.11/site-packages/ipykernel/iostream.py", line 648, in write
    self._schedule_flush()
  File "/Users/songzeyang/anaconda3/lib/python3.11/site-packages/ipykernel/iostream.py", line 545, in _schedule_flush
    self.pub_thread.schedule(_schedule_in_thread)
  File "/Users/songzeyang/anaconda3/lib/python3.11/site-packages/ipykernel/iostream.py", line 251, in schedule
    self._event_pipe.send(b"")
  File "/Users/songzeyang/anaconda3/lib/python3.11/site-packages/zmq/sugar/socket.py", line 618, in send
    return super().send(data, flags=flags, copy=copy, track=track)
           ^^^^^^^^^^^^^^^^^^^^^^^^^^^^^^^^^^^^^^^^^^^^^^^^^^^^^^^
  File "zmq/backend/cython/socket.pyx", line 740, in zmq.backend.cython.socket.Socket.send
  File "zmq/backend/cython/socket.pyx", line 781, in zmq.backend.cython.socket.Socket.send
  File "zmq/backend/cython/socket.pyx", line 137, in zmq.backend.cython.socket._check_closed
zmq.error.ZMQError: Socket operation on non-socket

During handling of the above exception, another exception occurred:

Traceback (most recent call last):
  File "/Users/songzeyang/anaconda3/lib/python3.11/site-packages/wandb/agents/pyagent.py", line 298, in _run_job
    self._function()
  File "/var/folders/50/9xzt17gx7hz47b3vjql39fjh0000gn/T/ipykernel_91700/3855940507.py", line 3, in train_n_validate
    with wandb.init(config=config):
  File "/Users/songzeyang/anaconda3/lib/python3.11/site-packages/wandb/sdk/wandb_run.py", line 3355, in __exit__
    traceback.print_exception(exc_type, exc_val, exc_tb)
  File "/Users/songzeyang/anaconda3/lib/python3.11/traceback.py", line 125, in print_exception
    te.print(file=file, chain=chain)
  File "/Users/songzeyang/anaconda3/lib/python3.11/traceback.py", line 982, in print
    print(line, file=file, end="")
  File "/Users/songzeyang/anaconda3/lib/python3.11/site-packages/wandb/sdk/lib/redirect.py", line 640, in write
    self._old_write(data)
  File "/Users/songzeyang/anaconda3/lib/python3.11/site-packages/ipykernel/iostream.py", line 648, in write
    self._schedule_flush()
  File "/Users/songzeyang/anaconda3/lib/python3.11/site-packages/ipykernel/iostream.py", line 545, in _schedule_flush
    self.pub_thread.schedule(_schedule_in_thread)
  File "/Users/songzeyang/anaconda3/lib/python3.11/site-packages/ipykernel/iostream.py", line 251, in schedule
    self._event_pipe.send(b"")
  File "/Users/songzeyang/anaconda3/lib/python3.11/site-packages/zmq/sugar/socket.py", line 618, in send
    return super().send(data, flags=flags, copy=copy, track=track)
           ^^^^^^^^^^^^^^^^^^^^^^^^^^^^^^^^^^^^^^^^^^^^^^^^^^^^^^^
  File "zmq/backend/cython/socket.pyx", line 740, in zmq.backend.cython.socket.Socket.send
  File "zmq/backend/cython/socket.pyx", line 781, in zmq.backend.cython.socket.Socket.send
  File "zmq/backend/cython/socket.pyx", line 137, in zmq.backend.cython.socket._check_closed
zmq.error.ZMQError: Socket operation on non-socket

During handling of the above exception, another exception occurred:

Traceback (most recent call last):
  File "/Users/songzeyang/anaconda3/lib/python3.11/site-packages/wandb/sdk/lib/ipython.py", line 113, in update
    self._progress.value = value
    ^^^^^^^^^^^^^^^^^^^^
  File "/Users/songzeyang/anaconda3/lib/python3.11/site-packages/traitlets/traitlets.py", line 729, in __set__
    self.set(obj, value)
  File "/Users/songzeyang/anaconda3/lib/python3.11/site-packages/traitlets/traitlets.py", line 718, in set
    obj._notify_trait(self.name, old_value, new_value)
  File "/Users/songzeyang/anaconda3/lib/python3.11/site-packages/traitlets/traitlets.py", line 1501, in _notify_trait
    self.notify_change(
  File "/Users/songzeyang/anaconda3/lib/python3.11/site-packages/ipywidgets/widgets/widget.py", line 693, in notify_change
    self.send_state(key=name)
  File "/Users/songzeyang/anaconda3/lib/python3.11/site-packages/ipywidgets/widgets/widget.py", line 579, in send_state
    self._send(msg, buffers=buffers)
  File "/Users/songzeyang/anaconda3/lib/python3.11/site-packages/ipywidgets/widgets/widget.py", line 818, in _send
    self.comm.send(data=msg, buffers=buffers)
  File "/Users/songzeyang/anaconda3/lib/python3.11/site-packages/comm/base_comm.py", line 113, in send
    self.publish_msg(
  File "/Users/songzeyang/anaconda3/lib/python3.11/site-packages/ipykernel/comm/comm.py", line 36, in publish_msg
    self.kernel.session.send(
  File "/Users/songzeyang/anaconda3/lib/python3.11/site-packages/jupyter_client/session.py", line 859, in send
    stream.send_multipart(to_send, copy=copy)
  File "/Users/songzeyang/anaconda3/lib/python3.11/site-packages/ipykernel/iostream.py", line 330, in send_multipart
    return self.io_thread.send_multipart(*args, **kwargs)
           ^^^^^^^^^^^^^^^^^^^^^^^^^^^^^^^^^^^^^^^^^^^^^^
  File "/Users/songzeyang/anaconda3/lib/python3.11/site-packages/ipykernel/iostream.py", line 260, in send_multipart
    self.schedule(lambda: self._really_send(*args, **kwargs))
  File "/Users/songzeyang/anaconda3/lib/python3.11/site-packages/ipykernel/iostream.py", line 251, in schedule
    self._event_pipe.send(b"")
  File "/Users/songzeyang/anaconda3/lib/python3.11/site-packages/zmq/sugar/socket.py", line 618, in send
    return super().send(data, flags=flags, copy=copy, track=track)
           ^^^^^^^^^^^^^^^^^^^^^^^^^^^^^^^^^^^^^^^^^^^^^^^^^^^^^^^
  File "zmq/backend/cython/socket.pyx", line 740, in zmq.backend.cython.socket.Socket.send
  File "zmq/backend/cython/socket.pyx", line 781, in zmq.backend.cython.socket.Socket.send
  File "zmq/backend/cython/socket.pyx", line 137, in zmq.backend.cython.socket._check_closed
zmq.error.ZMQError: Socket operation on non-socket
2024-01-30 16:02:52,072 INFO    Thread-11 (_run_job):91700 [wandb_run.py:_restore():2185] restore
2024-01-30 16:02:52,072 INFO    Thread-11 (_run_job):91700 [wandb_run.py:_restore():2191] restore done
2024-01-30 16:02:53,075 ERROR   Thread-11 (_run_job):91700 [wandb_run.py:_atexit_cleanup():2223] Problem finishing run
Traceback (most recent call last):
  File "/var/folders/50/9xzt17gx7hz47b3vjql39fjh0000gn/T/ipykernel_91700/3855940507.py", line 14, in train_n_validate
    print("The number of class in our training set is ", num_classes)
  File "/Users/songzeyang/anaconda3/lib/python3.11/site-packages/wandb/sdk/lib/redirect.py", line 640, in write
    self._old_write(data)
  File "/Users/songzeyang/anaconda3/lib/python3.11/site-packages/ipykernel/iostream.py", line 648, in write
    self._schedule_flush()
  File "/Users/songzeyang/anaconda3/lib/python3.11/site-packages/ipykernel/iostream.py", line 545, in _schedule_flush
    self.pub_thread.schedule(_schedule_in_thread)
  File "/Users/songzeyang/anaconda3/lib/python3.11/site-packages/ipykernel/iostream.py", line 251, in schedule
    self._event_pipe.send(b"")
  File "/Users/songzeyang/anaconda3/lib/python3.11/site-packages/zmq/sugar/socket.py", line 618, in send
    return super().send(data, flags=flags, copy=copy, track=track)
           ^^^^^^^^^^^^^^^^^^^^^^^^^^^^^^^^^^^^^^^^^^^^^^^^^^^^^^^
  File "zmq/backend/cython/socket.pyx", line 740, in zmq.backend.cython.socket.Socket.send
  File "zmq/backend/cython/socket.pyx", line 781, in zmq.backend.cython.socket.Socket.send
  File "zmq/backend/cython/socket.pyx", line 137, in zmq.backend.cython.socket._check_closed
zmq.error.ZMQError: Socket operation on non-socket

During handling of the above exception, another exception occurred:

Traceback (most recent call last):
  File "/Users/songzeyang/anaconda3/lib/python3.11/site-packages/wandb/agents/pyagent.py", line 298, in _run_job
    self._function()
  File "/var/folders/50/9xzt17gx7hz47b3vjql39fjh0000gn/T/ipykernel_91700/3855940507.py", line 3, in train_n_validate
    with wandb.init(config=config):
  File "/Users/songzeyang/anaconda3/lib/python3.11/site-packages/wandb/sdk/wandb_run.py", line 3355, in __exit__
    traceback.print_exception(exc_type, exc_val, exc_tb)
  File "/Users/songzeyang/anaconda3/lib/python3.11/traceback.py", line 125, in print_exception
    te.print(file=file, chain=chain)
  File "/Users/songzeyang/anaconda3/lib/python3.11/traceback.py", line 982, in print
    print(line, file=file, end="")
  File "/Users/songzeyang/anaconda3/lib/python3.11/site-packages/wandb/sdk/lib/redirect.py", line 640, in write
    self._old_write(data)
  File "/Users/songzeyang/anaconda3/lib/python3.11/site-packages/ipykernel/iostream.py", line 648, in write
    self._schedule_flush()
  File "/Users/songzeyang/anaconda3/lib/python3.11/site-packages/ipykernel/iostream.py", line 545, in _schedule_flush
    self.pub_thread.schedule(_schedule_in_thread)
  File "/Users/songzeyang/anaconda3/lib/python3.11/site-packages/ipykernel/iostream.py", line 251, in schedule
    self._event_pipe.send(b"")
  File "/Users/songzeyang/anaconda3/lib/python3.11/site-packages/zmq/sugar/socket.py", line 618, in send
    return super().send(data, flags=flags, copy=copy, track=track)
           ^^^^^^^^^^^^^^^^^^^^^^^^^^^^^^^^^^^^^^^^^^^^^^^^^^^^^^^
  File "zmq/backend/cython/socket.pyx", line 740, in zmq.backend.cython.socket.Socket.send
  File "zmq/backend/cython/socket.pyx", line 781, in zmq.backend.cython.socket.Socket.send
  File "zmq/backend/cython/socket.pyx", line 137, in zmq.backend.cython.socket._check_closed
zmq.error.ZMQError: Socket operation on non-socket

During handling of the above exception, another exception occurred:

Traceback (most recent call last):
  File "/Users/songzeyang/anaconda3/lib/python3.11/site-packages/wandb/sdk/lib/ipython.py", line 113, in update
    self._progress.value = value
    ^^^^^^^^^^^^^^^^^^^^
  File "/Users/songzeyang/anaconda3/lib/python3.11/site-packages/traitlets/traitlets.py", line 729, in __set__
    self.set(obj, value)
  File "/Users/songzeyang/anaconda3/lib/python3.11/site-packages/traitlets/traitlets.py", line 718, in set
    obj._notify_trait(self.name, old_value, new_value)
  File "/Users/songzeyang/anaconda3/lib/python3.11/site-packages/traitlets/traitlets.py", line 1501, in _notify_trait
    self.notify_change(
  File "/Users/songzeyang/anaconda3/lib/python3.11/site-packages/ipywidgets/widgets/widget.py", line 693, in notify_change
    self.send_state(key=name)
  File "/Users/songzeyang/anaconda3/lib/python3.11/site-packages/ipywidgets/widgets/widget.py", line 579, in send_state
    self._send(msg, buffers=buffers)
  File "/Users/songzeyang/anaconda3/lib/python3.11/site-packages/ipywidgets/widgets/widget.py", line 818, in _send
    self.comm.send(data=msg, buffers=buffers)
  File "/Users/songzeyang/anaconda3/lib/python3.11/site-packages/comm/base_comm.py", line 113, in send
    self.publish_msg(
  File "/Users/songzeyang/anaconda3/lib/python3.11/site-packages/ipykernel/comm/comm.py", line 36, in publish_msg
    self.kernel.session.send(
  File "/Users/songzeyang/anaconda3/lib/python3.11/site-packages/jupyter_client/session.py", line 859, in send
    stream.send_multipart(to_send, copy=copy)
  File "/Users/songzeyang/anaconda3/lib/python3.11/site-packages/ipykernel/iostream.py", line 330, in send_multipart
    return self.io_thread.send_multipart(*args, **kwargs)
           ^^^^^^^^^^^^^^^^^^^^^^^^^^^^^^^^^^^^^^^^^^^^^^
  File "/Users/songzeyang/anaconda3/lib/python3.11/site-packages/ipykernel/iostream.py", line 260, in send_multipart
    self.schedule(lambda: self._really_send(*args, **kwargs))
  File "/Users/songzeyang/anaconda3/lib/python3.11/site-packages/ipykernel/iostream.py", line 251, in schedule
    self._event_pipe.send(b"")
  File "/Users/songzeyang/anaconda3/lib/python3.11/site-packages/zmq/sugar/socket.py", line 618, in send
    return super().send(data, flags=flags, copy=copy, track=track)
           ^^^^^^^^^^^^^^^^^^^^^^^^^^^^^^^^^^^^^^^^^^^^^^^^^^^^^^^
  File "zmq/backend/cython/socket.pyx", line 740, in zmq.backend.cython.socket.Socket.send
  File "zmq/backend/cython/socket.pyx", line 781, in zmq.backend.cython.socket.Socket.send
  File "zmq/backend/cython/socket.pyx", line 137, in zmq.backend.cython.socket._check_closed
zmq.error.ZMQError: Socket operation on non-socket

During handling of the above exception, another exception occurred:

Traceback (most recent call last):
  File "/Users/songzeyang/anaconda3/lib/python3.11/site-packages/wandb/sdk/wandb_run.py", line 2211, in _atexit_cleanup
    self._on_finish()
  File "/Users/songzeyang/anaconda3/lib/python3.11/site-packages/wandb/sdk/wandb_run.py", line 2451, in _on_finish
    _ = exit_handle.wait(timeout=-1, on_progress=self._on_progress_exit)
        ^^^^^^^^^^^^^^^^^^^^^^^^^^^^^^^^^^^^^^^^^^^^^^^^^^^^^^^^^^^^^^^^
  File "/Users/songzeyang/anaconda3/lib/python3.11/site-packages/wandb/sdk/lib/mailbox.py", line 303, in wait
    on_progress(progress_handle)
  File "/Users/songzeyang/anaconda3/lib/python3.11/site-packages/wandb/sdk/wandb_run.py", line 2430, in _on_progress_exit
    self._footer_file_pusher_status_info(
  File "/Users/songzeyang/anaconda3/lib/python3.11/site-packages/wandb/sdk/wandb_run.py", line 3648, in _footer_file_pusher_status_info
    Run._footer_single_run_file_pusher_status_info(
  File "/Users/songzeyang/anaconda3/lib/python3.11/site-packages/wandb/sdk/wandb_run.py", line 3699, in _footer_single_run_file_pusher_status_info
    printer.progress_update(line, percent_done)
  File "/Users/songzeyang/anaconda3/lib/python3.11/site-packages/wandb/sdk/lib/printer.py", line 288, in progress_update
    self._progress.update(percent_done, text)
  File "/Users/songzeyang/anaconda3/lib/python3.11/site-packages/wandb/sdk/lib/ipython.py", line 121, in update
    wandb.termwarn(
  File "/Users/songzeyang/anaconda3/lib/python3.11/site-packages/wandb/errors/term.py", line 50, in termwarn
    _log(
  File "/Users/songzeyang/anaconda3/lib/python3.11/site-packages/wandb/errors/term.py", line 95, in _log
    click.echo(line, file=sys.stderr, nl=newline)
  File "/Users/songzeyang/anaconda3/lib/python3.11/site-packages/click/utils.py", line 299, in echo
    file.flush()
  File "/Users/songzeyang/anaconda3/lib/python3.11/site-packages/ipykernel/iostream.py", line 559, in flush
    self.pub_thread.schedule(self._flush)
  File "/Users/songzeyang/anaconda3/lib/python3.11/site-packages/ipykernel/iostream.py", line 251, in schedule
    self._event_pipe.send(b"")
  File "/Users/songzeyang/anaconda3/lib/python3.11/site-packages/zmq/sugar/socket.py", line 618, in send
    return super().send(data, flags=flags, copy=copy, track=track)
           ^^^^^^^^^^^^^^^^^^^^^^^^^^^^^^^^^^^^^^^^^^^^^^^^^^^^^^^
  File "zmq/backend/cython/socket.pyx", line 740, in zmq.backend.cython.socket.Socket.send
  File "zmq/backend/cython/socket.pyx", line 781, in zmq.backend.cython.socket.Socket.send
  File "zmq/backend/cython/socket.pyx", line 137, in zmq.backend.cython.socket._check_closed
zmq.error.ZMQError: Socket operation on non-socket
2024-01-30 16:05:07,288 INFO    MainThread:91700 [pyagent.py:run():314] Starting sweep agent: entity=None, project=None, count=5
2024-01-30 16:08:27,886 INFO    MainThread:91700 [pyagent.py:run():314] Starting sweep agent: entity=None, project=None, count=5
2024-01-30 16:11:12,546 INFO    MainThread:91700 [pyagent.py:run():314] Starting sweep agent: entity=None, project=None, count=5
2024-01-30 16:11:36,652 INFO    MainThread:91700 [wandb_setup.py:_flush():76] Current SDK version is 0.16.1
2024-01-30 16:11:36,652 INFO    MainThread:91700 [wandb_setup.py:_flush():76] Configure stats pid to 91700
2024-01-30 16:11:36,652 INFO    MainThread:91700 [wandb_setup.py:_flush():76] Loading settings from /Users/songzeyang/.config/wandb/settings
2024-01-30 16:11:36,652 INFO    MainThread:91700 [wandb_setup.py:_flush():76] Loading settings from /Users/songzeyang/Documents/GitHub/Data_Distill_with_NC/wandb/settings
2024-01-30 16:11:36,652 INFO    MainThread:91700 [wandb_setup.py:_flush():76] Loading settings from environment variables: {'project': 'hyper_sweep_4_neural_search', 'entity': 'data-distillation-with-nc', 'root_dir': '/Users/songzeyang/Documents/GitHub/Data_Distill_with_NC', 'run_id': 'yji3kod5', 'sweep_param_path': '/Users/songzeyang/Documents/GitHub/Data_Distill_with_NC/wandb/sweep-cqyijzfv/config-yji3kod5.yaml', 'sweep_id': 'cqyijzfv'}
2024-01-30 16:11:36,652 INFO    MainThread:91700 [wandb_setup.py:_flush():76] Applying setup settings: {'_disable_service': False}
2024-01-30 16:11:36,652 INFO    MainThread:91700 [wandb_setup.py:_flush():76] Inferring run settings from compute environment: {'program': '<python with no main file>'}
2024-01-30 16:11:36,652 INFO    MainThread:91700 [wandb_init.py:_log_setup():524] Logging user logs to /Users/songzeyang/Documents/GitHub/Data_Distill_with_NC/wandb/run-20240130_161136-yji3kod5/logs/debug.log
2024-01-30 16:11:36,652 INFO    MainThread:91700 [wandb_init.py:_log_setup():525] Logging internal logs to /Users/songzeyang/Documents/GitHub/Data_Distill_with_NC/wandb/run-20240130_161136-yji3kod5/logs/debug-internal.log
2024-01-30 16:11:36,652 INFO    MainThread:91700 [wandb_init.py:_jupyter_setup():470] configuring jupyter hooks <wandb.sdk.wandb_init._WandbInit object at 0x16b3b0e50>
2024-01-30 16:11:36,652 INFO    MainThread:91700 [wandb_init.py:init():564] calling init triggers
2024-01-30 16:11:36,652 INFO    MainThread:91700 [wandb_init.py:init():571] wandb.init called with sweep_config: {'batch_size': 64, 'depth': 4, 'epochs': 10, 'learning_rate': 0.1, 'loss': 'CrossEntropy', 'model': 'MLP', 'optimizer': 'Adam', 'width': 2048}
config: {'method': 'grid', 'metric': {'name': 'loss', 'goal': 'minimize'}, 'parameters': {'learning_rate': {'values': [0.1, 0.05, 0.001]}, 'optimizer': {'values': ['Adam', 'SGD', 'LBFGS']}, 'width': {'values': [1024, 2048, 4096]}, 'batch_size': {'values': [64, 256, 2048]}, 'model': {'values': ['ResNet18_adapt']}, 'epochs': {'value': 10}, 'loss': {'value': 'CrossEntropy'}}}
2024-01-30 16:11:36,652 INFO    MainThread:91700 [wandb_init.py:init():589] re-initializing run, found existing run on stack: yji3kod5
2024-01-30 16:11:36,653 INFO    MainThread:91700 [wandb_run.py:_finish():1962] finishing run data-distillation-with-nc/hyper_sweep_4_neural_search/yji3kod5
2024-01-30 16:11:36,654 INFO    MainThread:91700 [jupyter.py:save_history():445] not saving jupyter history
2024-01-30 16:11:36,654 INFO    MainThread:91700 [jupyter.py:save_ipynb():373] not saving jupyter notebook
2024-01-30 16:11:36,654 INFO    MainThread:91700 [wandb_init.py:_jupyter_teardown():452] cleaning up jupyter logic
